Com base no repoitorio anexado,

Houve um erro:

KeyError: 'type'
Traceback:
File "/Users/cliente/Desktop/projetos/PetCareAi/analytics/venv/lib/python3.13/site-packages/streamlit/runtime/scriptrunner/script_runner.py", line 535, in _run_script
    exec(code, module.__dict__)
    ~~~~^^^^^^^^^^^^^^^^^^^^^^^
File "/Users/cliente/Desktop/projetos/PetCareAi/analytics/app.py", line 6903, in <module>
    main()
    ~~~~^^
File "/Users/cliente/Desktop/projetos/PetCareAi/analytics/app.py", line 4445, in main
    if notification['type'] == 'warning':
       ~~~~~~~~~~~~^^^^^^^^

Mostre o caminho completo para cada codigo modificado
Forneça o código diretamente na conversa, e não em um artefato à direita.